Traceback (most recent call last):
  File "visualize_dots_v2.py", line 15, in <module>
    results=sys.argv[1]
IndexError: list index out of range
